<?xml version="1.0" encoding="utf-8"?>
<!-- This URDF was automatically created by SolidWorks to URDF Exporter! Originally created by Stephen Brawner (brawner@gmail.com) 
     Commit Version: 1.6.0-4-g7f85cfe  Build Version: 1.6.7995.38578
     For more information, please see http://wiki.ros.org/sw_urdf_exporter -->
<robot
  name="Trial1_URDFF">
  <link
    name="Body">
    <inertial>
      <origin
        xyz="0.116580062480921 0.203632414380905 0.267680810570905"
        rpy="0 0 0" />
      <mass
        value="2.87565345812485" />
      <inertia
        ixx="0.0127833675338013"
        ixy="-0.000217864160809355"
        ixz="9.99320302440465E-05"
        iyy="0.0227033370979438"
        iyz="0.000654848540411062"
        izz="0.0148322641741708" />
    </inertial>
    <visual>
      <origin
        xyz="0 0 0"
        rpy="0 0 0" />
      <geometry>
        <mesh
          filename="file:///home/sara/design2_ws/install/myrobot_sim/share/myrobot_sim/meshes/Body.STL" />
      </geometry>
      <material
        name="">
        <color
          rgba="0.745098039215686 0.737254901960784 0.729411764705882 1" />
      </material>
    </visual>
    <collision>
      <origin
        xyz="0 0 0"
        rpy="0 0 0" />
      <geometry>
        <mesh
          filename="file:///home/sara/design2_ws/install/myrobot_sim/share/myrobot_sim/meshes/Body.STL" />
      </geometry>
    </collision>
  </link>
  <link
    name="FR_Wheel">
    <inertial>
      <origin
        xyz="1.08802929635332E-06 0.0258289270072408 -7.54945366082671E-07"
        rpy="0 0 0" />
      <mass
        value="0.133116183813595" />
      <inertia
        ixx="0.000102729499110476"
        ixy="8.30896403571234E-10"
        ixz="-4.0913024860306E-10"
        iyy="0.000178046892056523"
        iyz="-6.48321417286034E-10"
        izz="0.000102730674803517" />
    </inertial>
    <visual>
      <origin
        xyz="0 0 0"
        rpy="0 0 0" />
      <geometry>
        <mesh
          filename="file:///home/sara/design2_ws/install/myrobot_sim/share/myrobot_sim/meshes/FR_Wheel.STL" />
      </geometry>
      <material
        name="">
        <color
          rgba="0.792156862745098 0.819607843137255 0.933333333333333 1" />
      </material>
    </visual>
    <collision>
      <origin
        xyz="0 0 0"
        rpy="0 0 0" />
      <geometry>
        <mesh
          filename="file:///home/sara/design2_ws/install/myrobot_sim/share/myrobot_sim/meshes/FR_Wheel.STL" />
      </geometry>
    </collision>
  </link>
  <joint
    name="FR_Joint"
    type="continuous">
    <origin
      xyz="0.22047 -0.43654 0.15136"
      rpy="3.1416 0 0" />
    <parent
      link="Body" />
    <child
      link="FR_Wheel" />
    <axis
      xyz="0 1 0" />
  </joint>
  <link
    name="RR_Wheel">
    <inertial>
      <origin
        xyz="7.18483049184232E-07 0.0258285967504086 8.33629088120569E-07"
        rpy="0 0 0" />
      <mass
        value="0.133123422628895" />
      <inertia
        ixx="0.000102735733538488"
        ixy="1.70774462781549E-09"
        ixz="6.6468007105172E-10"
        iyy="0.000178056302868726"
        iyz="-5.51818128952686E-11"
        izz="0.000102733129208732" />
    </inertial>
    <visual>
      <origin
        xyz="0 0 0"
        rpy="0 0 0" />
      <geometry>
        <mesh
          filename="file:///home/sara/design2_ws/install/myrobot_sim/share/myrobot_sim/meshes/RR_Wheel.STL" />
      </geometry>
      <material
        name="">
        <color
          rgba="0.792156862745098 0.819607843137255 0.933333333333333 1" />
      </material>
    </visual>
    <collision>
      <origin
        xyz="0 0 0"
        rpy="0 0 0" />
      <geometry>
        <mesh
          filename="file:///home/sara/design2_ws/install/myrobot_sim/share/myrobot_sim/meshes/RR_Wheel.STL" />
      </geometry>
    </collision>
  </link>
  <joint
    name="RR_Joint"
    type="continuous">
    <origin
      xyz="-0.02453 -0.43654 0.15136"
      rpy="3.1416 0 0" />
    <parent
      link="Body" />
    <child
      link="RR_Wheel" />
    <axis
      xyz="0 1 0" />
  </joint>
  <link
    name="FL_Wheel">
    <inertial>
      <origin
        xyz="7.14605758816989E-07 -0.0235185582608061 9.21027146327802E-07"
        rpy="0 0 0" />
      <mass
        value="0.133123193517618" />
      <inertia
        ixx="0.000102735278595089"
        ixy="1.91057527291506E-09"
        ixz="6.99571460195626E-10"
        iyy="0.000178056069065094"
        iyz="2.17602869163462E-10"
        izz="0.000102733259158633" />
    </inertial>
    <visual>
      <origin
        xyz="0 0 0"
        rpy="0 0 0" />
      <geometry>
        <mesh
          filename="file:///home/sara/design2_ws/install/myrobot_sim/share/myrobot_sim/meshes/FL_Wheel.STL" />
      </geometry>
      <material
        name="">
        <color
          rgba="0.792156862745098 0.819607843137255 0.933333333333333 1" />
      </material>
    </visual>
    <collision>
      <origin
        xyz="0 0 0"
        rpy="0 0 0" />
      <geometry>
        <mesh
          filename="file:///home/sara/design2_ws/install/myrobot_sim/share/myrobot_sim/meshes/FL_Wheel.STL" />
      </geometry>
    </collision>
  </link>
  <joint
    name="FL_Joint"
    type="continuous">
    <origin
      xyz="0.22047 -0.042196 0.15136"
      rpy="0 0.75159 0" />
    <parent
      link="Body" />
    <child
      link="FL_Wheel" />
    <axis
      xyz="0 1 0" />
  </joint>
  <link
    name="RL_Wheel">
    <inertial>
      <origin
        xyz="1.103839161673E-06 -0.0235183075452311 -7.57344712443153E-07"
        rpy="0 0 0" />
      <mass
        value="0.133116263866554" />
      <inertia
        ixx="0.000102729928254729"
        ixy="9.15882700731152E-10"
        ixz="-1.98367934020816E-10"
        iyy="0.000178047407248189"
        iyz="-6.33581216002572E-10"
        izz="0.000102730807314617" />
    </inertial>
    <visual>
      <origin
        xyz="0 0 0"
        rpy="0 0 0" />
      <geometry>
        <mesh
          filename="file:///home/sara/design2_ws/install/myrobot_sim/share/myrobot_sim/meshes/RL_Wheel.STL" />
      </geometry>
      <material
        name="">
        <color
          rgba="0.792156862745098 0.819607843137255 0.933333333333333 1" />
      </material>
    </visual>
    <collision>
      <origin
        xyz="0 0 0"
        rpy="0 0 0" />
      <geometry>
        <mesh
          filename="file:///home/sara/design2_ws/install/myrobot_sim/share/myrobot_sim/meshes/RL_Wheel.STL" />
      </geometry>
    </collision>
  </link>
  <joint
    name="RL_Wheel"
    type="continuous">
    <origin
      xyz="-0.02453 -0.042196 0.15136"
      rpy="-3.1416 -0.7065 -3.1416" />
    <parent
      link="Body" />
    <child
      link="RL_Wheel" />
    <axis
      xyz="0 1 0" />
  </joint>
  <link
    name="Hand_Pinion">
    <inertial>
      <origin
        xyz="0.131825819273133 0.038097338483273 -0.0449193990281507"
        rpy="0 0 0" />
      <mass
        value="0.0279777163922377" />
      <inertia
        ixx="6.58644207692729E-06"
        ixy="-4.28067607593132E-12"
        ixz="-7.72951918206092E-14"
        iyy="6.58655671957757E-06"
        iyz="-1.90612073191498E-08"
        izz="1.27219666968974E-05" />
    </inertial>
    <visual>
      <origin
        xyz="0 0 0"
        rpy="0 0 0" />
      <geometry>
        <mesh
          filename="file:///home/sara/design2_ws/install/myrobot_sim/share/myrobot_sim/meshes/Hand_Pinion.STL" />
      </geometry>
      <material
        name="">
        <color
          rgba="0.792156862745098 0.819607843137255 0.933333333333333 1" />
      </material>
    </visual>
    <collision>
      <origin
        xyz="0 0 0"
        rpy="0 0 0" />
      <geometry>
        <mesh
          filename="file:///home/sara/design2_ws/install/myrobot_sim/share/myrobot_sim/meshes/Hand_Pinion.STL" />
      </geometry>
    </collision>
  </link>
  <joint
    name="Hand_Pinion_Joint"
    type="fixed">
    <origin
      xyz="0.37637 -0.29604 0.19546"
      rpy="1.5677 -1.0632 1.5616" />
    <parent
      link="Body" />
    <child
      link="Hand_Pinion" />
    <axis
      xyz="0 0 0" />
  </joint>
  <link
    name="Top_Rack">
    <inertial>
      <origin
        xyz="0.0655187436838316 0.0260605324140515 -0.0107485152761947"
        rpy="0 0 0" />
      <mass
        value="0.0444721142326125" />
      <inertia
        ixx="4.31970255875435E-05"
        ixy="6.13571137842869E-06"
        ixz="-9.40769489791592E-06"
        iyy="4.44077713560118E-05"
        iyz="8.25852136933452E-06"
        izz="3.99224131601701E-05" />
    </inertial>
    <visual>
      <origin
        xyz="0 0 0"
        rpy="0 0 0" />
      <geometry>
        <mesh
          filename="file:///home/sara/design2_ws/install/myrobot_sim/share/myrobot_sim/meshes/Top_Rack.STL" />
      </geometry>
      <material
        name="">
        <color
          rgba="0.792156862745098 0.819607843137255 0.933333333333333 1" />
      </material>
    </visual>
    <collision>
      <origin
        xyz="0 0 0"
        rpy="0 0 0" />
      <geometry>
        <mesh
          filename="file:///home/sara/design2_ws/install/myrobot_sim/share/myrobot_sim/meshes/Top_Rack.STL" />
      </geometry>
    </collision>
  </link>
  <joint
    name="Top_Rack_Joint"
    type="fixed">
    <origin
      xyz="-0.103696936304551 0.383278535088452 0.00131398051809067"
      rpy="-0.00159656794114636 0.00271507286217638 -1.06315566074658" />
    <parent
      link="Hand_Pinion" />
    <child
      link="Top_Rack" />
    <axis
      xyz="0 0 0" />
  </joint>
  <link
    name="Bottom_Rack">
    <inertial>
      <origin
        xyz="0.19566277095261 0.00208141977650605 -0.0103076282850985"
        rpy="0 0 0" />
      <mass
        value="0.0441284936633414" />
      <inertia
        ixx="3.28534224276309E-05"
        ixy="1.02768005051773E-06"
        ixz="5.79231186575885E-06"
        iyy="3.90577936930602E-05"
        iyz="-6.97966423222986E-07"
        izz="3.2866699364524E-05" />
    </inertial>
    <visual>
      <origin
        xyz="0 0 0"
        rpy="0 0 0" />
      <geometry>
        <mesh
          filename="file:///home/sara/design2_ws/install/myrobot_sim/share/myrobot_sim/meshes/Bottom_Rack.STL" />
      </geometry>
      <material
        name="">
        <color
          rgba="0.792156862745098 0.819607843137255 0.933333333333333 1" />
      </material>
    </visual>
    <collision>
      <origin
        xyz="0 0 0"
        rpy="0 0 0" />
      <geometry>
        <mesh
          filename="file:///home/sara/design2_ws/install/myrobot_sim/share/myrobot_sim/meshes/Bottom_Rack.STL" />
      </geometry>
    </collision>
  </link>
  <joint
    name="Bottom_Rack_Joint"
    type="fixed">
    <origin
      xyz="0.0418904539383234 0.121725721880754 0.000551744829093981"
      rpy="-0.00159656794149612 0.00271507286217637 -1.06315566074658" />
    <parent
      link="Hand_Pinion" />
    <child
      link="Bottom_Rack" />
    <axis
      xyz="0 0 0" />
  </joint>
  <link
    name="Pinion_Rotation">
    <inertial>
      <origin
        xyz="-1.21915135264938E-07 2.12968309654116E-10 -0.00862698330520303"
        rpy="0 0 0" />
      <mass
        value="0.01971261332238" />
      <inertia
        ixx="2.49320505899689E-06"
        ixy="-1.92363808123588E-14"
        ixz="-3.95214159642005E-11"
        iyy="2.49246744458359E-06"
        iyz="6.34867153675314E-14"
        izz="3.84795949836166E-06" />
    </inertial>
    <visual>
      <origin
        xyz="0 0 0"
        rpy="0 0 0" />
      <geometry>
        <mesh
          filename="file:///home/sara/design2_ws/install/myrobot_sim/share/myrobot_sim/meshes/Pinion_Rotation.STL" />
      </geometry>
      <material
        name="">
        <color
          rgba="0.792156862745098 0.819607843137255 0.933333333333333 1" />
      </material>
    </visual>
    <collision>
      <origin
        xyz="0 0 0"
        rpy="0 0 0" />
      <geometry>
        <mesh
          filename="file:///home/sara/design2_ws/install/myrobot_sim/share/myrobot_sim/meshes/Pinion_Rotation.STL" />
      </geometry>
    </collision>
  </link>
  <joint
    name="Pinion_Rotation_Joint"
    type="continuous">
    <origin
      xyz="0.278337471500002 -0.333499551278806 0.190972134142356"
      rpy="-3.14159265358979 0 -0.454860647536355" />
    <parent
      link="Body" />
    <child
      link="Pinion_Rotation" />
    <axis
      xyz="0 0 1" />
  </joint>
  <link
    name="Gear_Rotation">
    <inertial>
      <origin
        xyz="-0.0396180351540131 0.0329007638784696 -0.00128077100890733"
        rpy="0 0 0" />
      <mass
        value="0.423176632975611" />
      <inertia
        ixx="0.000353571930390184"
        ixy="-1.33192920557063E-05"
        ixz="2.56201793177061E-06"
        iyy="0.000415654470762434"
        iyz="2.44567187586392E-06"
        izz="0.00041385318087561" />
    </inertial>
    <visual>
      <origin
        xyz="0 0 0"
        rpy="0 0 0" />
      <geometry>
        <mesh
          filename="file:///home/sara/design2_ws/install/myrobot_sim/share/myrobot_sim/meshes/Gear_Rotation.STL" />
      </geometry>
      <material
        name="">
        <color
          rgba="0.745098039215686 0.737254901960784 0.729411764705882 1" />
      </material>
    </visual>
    <collision>
      <origin
        xyz="0 0 0"
        rpy="0 0 0" />
      <geometry>
        <mesh
          filename="file:///home/sara/design2_ws/install/myrobot_sim/share/myrobot_sim/meshes/Gear_Rotation.STL" />
      </geometry>
    </collision>
  </link>
  <joint
    name="Gear_Rotation_Joint"
    type="fixed">
    <origin
      xyz="-0.0389759454733984 -0.0581452979566263 -0.0599338066051831"
      rpy="1.12508859946175 -1.5707963267949 0" />
    <parent
      link="Pinion_Rotation" />
    <child
      link="Gear_Rotation" />
    <axis
      xyz="0 0 0" />
  </joint>
</robot>